<mujoco model="inverted_pendulum">
  <option timestep="0.002" gravity="0 0 -9.81" integrator="implicitfast"/>
  <size nconmax="50" njmax="50"/>

  <visual>
    <headlight diffuse="0.6 0.6 0.6" ambient="0.3 0.3 0.3" specular="0 0 0"/>
    <rgba haze="0.15 0.25 0.35 1"/>
    <global azimuth="120" elevation="-20"/>
    <scale contactwidth="0.075" contactheight="0.025" forcewidth="0.05" com="0.05" framewidth="0.01" framelength="0.2"/>
  </visual>

  <asset>
    <texture type="skybox" builtin="gradient" rgb1="0.3 0.5 0.7" rgb2="0 0 0" width="512" height="3072"/>
    <texture type="2d" name="groundplane" builtin="checker" mark="edge"
             rgb1="0.2 0.3 0.4" rgb2="0.1 0.2 0.3"
             markrgb="0.8 0.8 0.8" width="300" height="300"/>
    <material name="groundplane" texture="groundplane" texuniform="true" texrepeat="5 5" reflectance="0.2"/>
  </asset>

  <default>
    <joint damping="0.001" armature="0.0"/>
    <geom  condim="3" friction="0.8 0.01 0.001" solref="0.005 1" solimp="0.9 0.9 0.01"/>
  </default>

  <worldbody>
    <light pos="0 0 1.5" dir="0 0 -1" directional="true"/>
    <geom name="floor" size="0 0 0.05" type="plane" material="groundplane" contype="1"/>

    <!-- Inverted pendulum base -->
    <body name="pole" pos="0 0 0">
      <!-- Hinge about Y so motion is in the X-Z plane -->
      <joint name="hinge" type="hinge" axis="0 1 0" limited="false"/>

      <!-- Base visual -->
      <geom type="sphere" pos="0 0 0" size="0.05" rgba="1 0 0 1"/>

      <!-- Rod geometry -->
      <geom name="rod" type="capsule" fromto="0 0 0  0 0 1.0" size="0.02" rgba="0.1 0 0 1" mass="1.0"/>

      <!-- Top attachment point -->
      <body name="top_attachment" pos="0 0 1.0">
        <!-- Ball joint at top -->
        <joint name="top_ball" type="ball"/>
        <!-- Visual sphere to mark the top -->
        <geom type="sphere" size="0.08" rgba="0 1 0 1"/>
      </body>
    </body>
  </worldbody>

  <actuator>
    <!-- Torque motor on hinge -->
    <motor name="hinge_torque" joint="hinge" gear="1" ctrllimited="true" ctrlrange="-10 10"/>
  </actuator>
</mujoco>
